[2025-05-08T21:26:32.581+0000] {taskinstance.py:1956} INFO - Dependencies all met for dep_context=non-requeueable deps ti=<TaskInstance: elt_IBGE.processar_dados_ibge manual__2025-05-08T21:26:31.185671+00:00 [queued]>
[2025-05-08T21:26:32.590+0000] {taskinstance.py:1956} INFO - Dependencies all met for dep_context=requeueable deps ti=<TaskInstance: elt_IBGE.processar_dados_ibge manual__2025-05-08T21:26:31.185671+00:00 [queued]>
[2025-05-08T21:26:32.591+0000] {taskinstance.py:2170} INFO - Starting attempt 1 of 1
[2025-05-08T21:26:32.673+0000] {taskinstance.py:2191} INFO - Executing <Task(_PythonDecoratedOperator): processar_dados_ibge> on 2025-05-08 21:26:31.185671+00:00
[2025-05-08T21:26:32.678+0000] {standard_task_runner.py:60} INFO - Started process 192 to run task
[2025-05-08T21:26:32.681+0000] {standard_task_runner.py:87} INFO - Running: ['***', 'tasks', 'run', 'elt_IBGE', 'processar_dados_ibge', 'manual__2025-05-08T21:26:31.185671+00:00', '--job-id', '9', '--raw', '--subdir', 'DAGS_FOLDER/etl.py', '--cfg-path', '/tmp/tmplxhgf04h']
[2025-05-08T21:26:32.683+0000] {standard_task_runner.py:88} INFO - Job 9: Subtask processar_dados_ibge
[2025-05-08T21:26:32.793+0000] {task_command.py:423} INFO - Running <TaskInstance: elt_IBGE.processar_dados_ibge manual__2025-05-08T21:26:31.185671+00:00 [running]> on host 60608213aa39
[2025-05-08T21:26:32.968+0000] {taskinstance.py:2480} INFO - Exporting env vars: AIRFLOW_CTX_DAG_OWNER='***' AIRFLOW_CTX_DAG_ID='elt_IBGE' AIRFLOW_CTX_TASK_ID='processar_dados_ibge' AIRFLOW_CTX_EXECUTION_DATE='2025-05-08T21:26:31.185671+00:00' AIRFLOW_CTX_TRY_NUMBER='1' AIRFLOW_CTX_DAG_RUN_ID='manual__2025-05-08T21:26:31.185671+00:00'
[2025-05-08T21:26:33.172+0000] {taskinstance.py:2698} ERROR - Task failed with exception
Traceback (most recent call last):
  File "/home/airflow/.local/lib/python3.11/site-packages/airflow/models/taskinstance.py", line 433, in _execute_task
    result = execute_callable(context=context, **execute_callable_kwargs)
             ^^^^^^^^^^^^^^^^^^^^^^^^^^^^^^^^^^^^^^^^^^^^^^^^^^^^^^^^^^^^
  File "/home/airflow/.local/lib/python3.11/site-packages/airflow/decorators/base.py", line 241, in execute
    return_value = super().execute(context)
                   ^^^^^^^^^^^^^^^^^^^^^^^^
  File "/home/airflow/.local/lib/python3.11/site-packages/airflow/operators/python.py", line 199, in execute
    return_value = self.execute_callable()
                   ^^^^^^^^^^^^^^^^^^^^^^^
  File "/home/airflow/.local/lib/python3.11/site-packages/airflow/operators/python.py", line 216, in execute_callable
    return self.python_callable(*self.op_args, **self.op_kwargs)
           ^^^^^^^^^^^^^^^^^^^^^^^^^^^^^^^^^^^^^^^^^^^^^^^^^^^^^
  File "/opt/airflow/dags/etl.py", line 25, in processar_dados_ibge
    .getOrCreate()
     ^^^^^^^^^^^^^
  File "/home/airflow/.local/lib/python3.11/site-packages/pyspark/sql/session.py", line 497, in getOrCreate
    sc = SparkContext.getOrCreate(sparkConf)
         ^^^^^^^^^^^^^^^^^^^^^^^^^^^^^^^^^^^
  File "/home/airflow/.local/lib/python3.11/site-packages/pyspark/context.py", line 515, in getOrCreate
    SparkContext(conf=conf or SparkConf())
  File "/home/airflow/.local/lib/python3.11/site-packages/pyspark/context.py", line 201, in __init__
    SparkContext._ensure_initialized(self, gateway=gateway, conf=conf)
  File "/home/airflow/.local/lib/python3.11/site-packages/pyspark/context.py", line 436, in _ensure_initialized
    SparkContext._gateway = gateway or launch_gateway(conf)
                                       ^^^^^^^^^^^^^^^^^^^^
  File "/home/airflow/.local/lib/python3.11/site-packages/pyspark/java_gateway.py", line 107, in launch_gateway
    raise PySparkRuntimeError(
pyspark.errors.exceptions.base.PySparkRuntimeError: [JAVA_GATEWAY_EXITED] Java gateway process exited before sending its port number.
[2025-05-08T21:26:33.188+0000] {taskinstance.py:1138} INFO - Marking task as FAILED. dag_id=elt_IBGE, task_id=processar_dados_ibge, execution_date=20250508T212631, start_date=20250508T212632, end_date=20250508T212633
[2025-05-08T21:26:33.235+0000] {standard_task_runner.py:107} ERROR - Failed to execute job 9 for task processar_dados_ibge ([JAVA_GATEWAY_EXITED] Java gateway process exited before sending its port number.; 192)
[2025-05-08T21:26:33.254+0000] {local_task_job_runner.py:234} INFO - Task exited with return code 1
[2025-05-08T21:26:33.277+0000] {taskinstance.py:3280} INFO - 0 downstream tasks scheduled from follow-on schedule check
